<?xml version="1.0"?>

<robot xmlns:xacro="http://www.ros.org/wiki/xacro">

<xacro:macro name="ball" params="prefix parent child *origin">

  <joint name="${prefix}_joint" type="continuous">
    <xacro:insert_block name="origin" />
    <parent link="${parent}"/>
    <child link="junta1"/>
    <axis xyz="0 1 0" />
  </joint>

  <link name="junta1">
    <inertial>
      <mass value="0.25" />
      <!-- <origin xyz="${offset_x } ${offset_y} ${offset_z}" rpy="0 0 0" /> -->
      <inertia ixx="5.8083e-4" ixy="0" ixz="0" iyy="3.0833e-5" iyz="0" izz="5.9083e-4" />
    </inertial>
  </link>

  <joint name="${prefix}_joint2" type="continuous">
    <!-- <xacro:insert_block name="origin" /> -->
    <parent link="junta1"/>
    <child link="junta2"/>
    <axis xyz="0 0 1" />
  </joint>

  <link name="junta2">
    <inertial>
      <mass value="0.25" />
      <!-- <origin xyz="${offset_x } ${offset_y} ${offset_z}" rpy="0 0 0" /> -->
      <inertia ixx="5.8083e-4" ixy="0" ixz="0" iyy="3.0833e-5" iyz="0" izz="5.9083e-4" />
    </inertial>  
  </link>

  <joint name="${prefix}_joint3" type="continuous">
    <!-- <xacro:insert_block name="origin" /> -->
    <parent link="junta1"/>
    <child link="junta3"/>
    <axis xyz="1 0 0" />
  </joint>

  <link name="junta3">
    <inertial>
      <mass value="0.25" />
      <!-- <origin xyz="${offset_x } ${offset_y} ${offset_z}" rpy="0 0 0" /> -->
      <inertia ixx="5.8083e-4" ixy="0" ixz="0" iyy="3.0833e-5" iyz="0" izz="5.9083e-4" />
    </inertial>  
  </link>

<joint name="${prefix}_jointfixed" type="fixed">
    <!-- <xacro:insert_block name="origin" />     -->
    <!-- <origin xyz="${offset_x } ${offset_y} ${offset_z}" rpy="0 0 0" /> -->
    <parent link="junta3"/>
    <child link="${child}"/>
    <limit effort="1000" velocity="1000" />
    <joint_properties damping="0.0" friction="0.0" />
    <anchor xyz="0 0 0" />
  </joint>
</xacro:macro>

</robot>